<?xml version="1.0" encoding="utf-8"?>
<robot
  name="moolabot">
<!--Material Colors-->
  <material name="black">
    <color rgba="0.0 0.0 0.0 1.0"/>
  </material>
  <material name="blue">
    <color rgba="0.203125 0.23828125 0.28515625 1.0"/>
  </material>
  <material name="green">
    <color rgba="0.0 0.8 0.0 1.0"/>
  </material>
  <material name="grey">
    <color rgba="0.2 0.2 0.2 1.0"/>
  </material>
  <material name="orange">
    <color rgba="1.0 0.423529411765 0.0392156862745 1.0"/>
  </material>
  <material name="brown">
    <color rgba="0.870588235294 0.811764705882 0.764705882353 1.0"/>
  </material>
  <material name="red">
    <color rgba="0.80078125 0.12890625 0.1328125 1.0"/>
  </material>
  <material name="white">
    <color rgba="1.0 1.0 1.0 1.0"/>
  </material>
  
<!--Gazebo Colors-->
  <gazebo reference="base_link">
    <material>Gazebo/Orange</material>
  </gazebo>
  <gazebo reference="moolabot_front_right_wheel">
    <material>Gazebo/Black</material>
  </gazebo>
  <gazebo reference="moolabot_front_left_wheel">
    <material>Gazebo/Black</material>
  </gazebo>  
  <gazebo reference="moolabot_rear_right_rocker_rear_wheel">
    <material>Gazebo/Black</material>
  </gazebo>  
  <gazebo reference="moolabot_rear_right_rocker_center_wheel">
    <material>Gazebo/Black</material>
  </gazebo>  
  <gazebo reference="moolabot_rear_left_rocker_rear_wheel">
    <material>Gazebo/Black</material>
  </gazebo>  
  <gazebo reference="moolabot_rear_left_rocker_center_wheel">
    <material>Gazebo/Black</material>
  </gazebo>  
  <gazebo reference="moolabot_battery">
    <material>Gazebo/Blue</material>
  </gazebo>    

<!--base_link-->  
  <link
    name="base_link">
    <inertial>
      <origin
        xyz="0 0 0"
        rpy="0 0 0" />
      <mass
        value="2.8701" />
      <inertia
        ixx="0.019918"
        ixy="0"
        ixz="0"
        iyy="0.042638"
        iyz="0"
        izz="0.061874" />
    </inertial>
    <visual>
      <origin
        xyz="0 0 0"
        rpy="0 0 0" />
      <geometry>
        <box size="0.42 0.345 0.02"/>
      </geometry>
      <material
        name="orange">
      </material>
    </visual>
    <collision>
      <origin
        xyz="0 0 0"
        rpy="0 0 0" />
      <geometry>
        <box size="0.42 0.345 0.02"/>
      </geometry>
    </collision>
  </link>
<!-- Front Right Wheel-->
  <link
    name="moolabot_front_right_wheel">
    <inertial>
      <origin
        xyz="0 0 0"
        rpy="0 0 0" />
      <mass
        value="2.2" />
      <inertia
        ixx="0.005892"
        ixy="0"
        ixz="0"
        iyy="0.005892"
        iyz="0"
        izz="0.010838" />
    </inertial>
    <visual>
      <origin
        xyz="0 0 0"
        rpy="0 0 0" />
      <geometry>
        <cylinder length="0.0435" radius="0.085"/>
      </geometry>
      <material
        name="black">
      </material>
    </visual>
    <collision>
      <origin
        xyz="0 0 0"
        rpy="0 0 0" />
      <geometry>
        <cylinder length="0.0435" radius="0.085"/>
      </geometry>
    </collision>
  </link>
  <joint
    name="moolabot_front_right_joint"
    type="continuous">
    <origin
      xyz="0.14829 -0.23736 0.003175"
      rpy="-1.57 0 0" />
    <parent
      link="base_link" />
    <child
      link="moolabot_front_right_wheel" />
    <axis
      xyz="0 0 1" />
   </joint>
<!--Front Left Wheel -->
   <link
    name="moolabot_front_left_wheel">
    <inertial>
      <origin
        xyz="0 0 0"
        rpy="0 0 0" />
      <mass
        value="2.2" />
      <inertia
        ixx="0.005892"
        ixy="0"
        ixz="0"
        iyy="0.005892"
        iyz="0"
        izz="0.010838" />
	</inertial>
    <visual>
      <origin
        xyz="0 0 0"
        rpy="0 0 0" />
      <geometry>
        <cylinder length="0.0435" radius="0.085"/>
      </geometry>
      <material
        name="black">
      </material>
    </visual>
    <collision>
      <origin
        xyz="0 0 0"
        rpy="0 0 0" />
      <geometry>
        <cylinder length="0.0435" radius="0.085"/>
      </geometry>
    </collision>
  </link>
  <joint
    name="moolabot_front_left_joint"
    type="continuous">
    <origin
      xyz="0.14829 0.23736 0.003175"
      rpy="-1.57 0 0" />
    <parent
      link="base_link" />
    <child
      link="moolabot_front_left_wheel" />
    <axis
      xyz="0 0 1" /> 
   </joint>
<!-- Right rocker -->
   <link
    name="moolabot_rear_right_rocker">
    <inertial>
      <origin
        xyz="0 0 0"
        rpy="0 0 0" />
      <mass
        value="0.32911" />
      <inertia
        ixx="0.00015526"
        ixy="0"
        ixz="0"
        iyy="0.0020318"
        iyz="0"
        izz="0.0018788" />
    </inertial>
    <visual>
      <origin
        xyz="0 0 0"
        rpy="0 0 0" />
      <geometry>
        <box size="0.28 0.01 0.08" />
      </geometry>
      <material
        name="white">
      </material>
    </visual>
    <collision>
      <origin
        xyz="0 0 0"
        rpy="0 0 0" />
      <geometry>
        <box size="0.28 0.01 0.08" />
      </geometry>
    </collision>
  </link>
  <joint
    name="moolabot_rear_right_joint"
    type="revolute">
    <origin
      xyz="-0.15651 -0.20097 0.003175"
      rpy="0 0 0" />
    <parent
      link="base_link" />
    <child
      link="moolabot_rear_right_rocker" />
    <axis
      xyz="0 1 0" />
	  <limit effort="10000" velocity="100" lower="-0.523" upper="0.523"/>
	  <joint_properties damping="0.0" friction="0"/>
  </joint>
<!-- Right Rear Wheel-->
  <link
    name="moolabot_rear_right_rocker_rear_wheel">
    <inertial>
      <origin
        xyz="0 0 0"
        rpy="0 0 0" />
      <mass
        value="2.2" />
      <inertia
        ixx="0.005892"
        ixy="0"
        ixz="0"
        iyy="0.005892"
        iyz="0"
        izz="0.010838" />
    </inertial>
    <visual>
      <origin
        xyz="0 0 0"
        rpy="0 0 0" />
      <geometry>
        <cylinder length="0.0435" radius="0.085"/>
      </geometry>
      <material
        name="black">
      </material>
    </visual>
    <collision>
      <origin
        xyz="0 0 0"
        rpy="0 0 0" />
      <geometry>
        <cylinder length="0.0435" radius="0.085"/>
      </geometry>
    </collision>
  </link>
  <joint
    name="moolabot_rear_right_rocker_rear_joint"
    type="continuous">
    <origin
      xyz="-0.1016 -0.0364 0"
      rpy="-1.57 0 0" />
    <parent
      link="moolabot_rear_right_rocker" />
    <child
      link="moolabot_rear_right_rocker_rear_wheel" />
    <axis
      xyz="0 0 1" />
  </joint> 
<!-- Right Center Wheel -->
  <link
    name="moolabot_rear_right_rocker_center_wheel">
    <inertial>
      <origin
        xyz="0 0 0"
        rpy="0 0 0" />
      <mass
        value="2.2" />
      <inertia
        ixx="0.005892"
        ixy="0"
        ixz="0"
        iyy="0.005892"
        iyz="0"
        izz="0.010838" />
    </inertial>
    <visual>
      <origin
        xyz="0 0 0"
        rpy="0 0 0" />
      <geometry>
        <cylinder length="0.0435" radius="0.085"/>
      </geometry>
      <material
        name="black">
      </material>
    </visual>
    <collision>
      <origin
        xyz="0 0 0"
        rpy="0 0 0" />
      <geometry>
        <cylinder length="0.0435" radius="0.085"/>
      </geometry>
    </collision>
  </link>
  <joint
    name="moolabot_rear_right_rocker_center_joint"
    type="continuous">
    <origin
      xyz="0.1016 -0.0364 0"
      rpy="-1.57 0 0" />
    <parent
      link="moolabot_rear_right_rocker" />
    <child
      link="moolabot_rear_right_rocker_center_wheel" />
    <axis
      xyz="0 0 1" /> 
  </joint>
<!-- Rocker Left -->
  <link
    name="moolabot_rear_left_rocker">
    <inertial>
      <origin
        xyz="0 0 0"
        rpy="0 0 0" />
      <mass
        value="0.32911" />
      <inertia
        ixx="0.00015526"
        ixy="0"
        ixz="0"
        iyy="0.0020318"
        iyz="0"
        izz="0.0018788" />
    </inertial>
    <visual>
      <origin
        xyz="0 0 0"
        rpy="0 0 0" />
      <geometry>
        <box size="0.28 0.01 0.08" />
      </geometry>
      <material
        name="white">
      </material>
    </visual>
    <collision>
      <origin
        xyz="0 0 0"
        rpy="0 0 0" />
      <geometry>
        <box size="0.28 0.01 0.08" />
      </geometry>
    </collision>
  </link>
  <joint
    name="moolabot_rear_left_joint"
    type="revolute">
    <origin
      xyz="-0.15651 0.20097 0.003175"
      rpy="0 0 0" />
    <parent
      link="base_link" />
    <child
      link="moolabot_rear_left_rocker" />
    <axis
      xyz="0 1 0" />
	  <limit effort="10000" velocity="100" lower="-0.523" upper="0.523"/>
	  <joint_properties damping="0" friction="0"/>
  </joint>
<!-- Left Rear Wheel -->
  <link
    name="moolabot_rear_left_rocker_rear_wheel">
    <inertial>
      <origin
        xyz="0 0 0"
        rpy="0 0 0" />
      <mass
        value="2.2" />
      <inertia
        ixx="0.005892"
        ixy="0"
        ixz="0"
        iyy="0.005892"
        iyz="0"
        izz="0.010838" />
    </inertial>
    <visual>
      <origin
        xyz="0 0 0"
        rpy="0 0 0" />
      <geometry>
        <cylinder length="0.0435" radius="0.085"/>
      </geometry>
      <material
        name="black">
      </material>
    </visual>
    <collision>
      <origin
        xyz="0 0 0"
        rpy="0 0 0" />
      <geometry>
        <cylinder length="0.0435" radius="0.085"/>
      </geometry>
    </collision>
  </link>
  <joint
    name="moolabot_rear_left_rocker_rear_joint"
    type="continuous">
    <origin
      xyz="-0.1016 0.0364 0"
      rpy="-1.57 0 0" />
    <parent
      link="moolabot_rear_left_rocker" />
    <child
      link="moolabot_rear_left_rocker_rear_wheel" />
    <axis
      xyz="0 0 1" />
  </joint>
<!-- Left Center Wheel-->
  <link
    name="moolabot_rear_left_rocker_center_wheel">
    <inertial>
      <origin
        xyz="0 0 0"
        rpy="0 0 0" />
      <mass
        value="2.2" />
      <inertia
        ixx="0.005892"
        ixy="0"
        ixz="0"
        iyy="0.005892"
        iyz="0"
        izz="0.010838" />
    </inertial>
    <visual>
      <origin
        xyz="0 0 0"
        rpy="0 0 0" />
      <geometry>
        <cylinder length="0.0435" radius="0.085"/>
      </geometry>
      <material
        name="black">
      </material>
    </visual>
    <collision>
      <origin
        xyz="0 0 0"
        rpy="0 0 0" />
      <geometry>
        <cylinder length="0.0435" radius="0.085"/>
      </geometry>
    </collision>
  </link>
  <joint
    name="moolabot_rear_left_rocker_center_joint"
    type="continuous">
    <origin
      xyz="0.1016 0.0364 0"
      rpy="-1.57 0 0" />
    <parent
      link="moolabot_rear_left_rocker" />
    <child
      link="moolabot_rear_left_rocker_center_wheel" />
    <axis
      xyz="0 0 1" />
  </joint>
<!-- Battery -->
  <link
    name="moolabot_battery">
    <inertial>
      <origin
        xyz="0 0 0"
        rpy="0 0 0" />
      <mass
        value="7" />
      <inertia
        ixx="6.716561"
        ixy="0"
        ixz="0"
        iyy="13.36388"
        iyz="0"
        izz="4.891684" />
    </inertial>
    <visual>
      <origin
        xyz="0 0 0"
        rpy="0 0 0" />
      <geometry>
        <box size="0.285 0.20 0.075" />
      </geometry>
      <material
        name="blue">
      </material>
    </visual>
    <collision>
      <origin
        xyz="0 0 0"
        rpy="0 0 0" />
      <geometry>
        <box size="0.285 0.20 0.075" />
      </geometry>
    </collision>
  </link>
  <joint
    name="moolabot_battery_joint"
    type="fixed">
    <origin
      xyz="0 0 0.0375"
      rpy="0 0 0" />
    <parent
      link="base_link" />
    <child
      link="moolabot_battery" />
    <axis
      xyz="0 0 0" />
  </joint>  
<!--   <link
    name="lidar1">
     <inertial>
      <mass value="0.1"/>
      <inertia ixx="0.001" ixy="0" ixz="0"
               iyy="0.001" iyz="0"
               izz="0.001" />
    </inertial>
    <visual>
      <origin
        xyz="0 0 0"
        rpy="0 0 0" />
      <geometry>
        <mesh
          filename="package://moolabot/meshes/lidar.stl" />
      </geometry>
      <material
        name="White">
        <color
          rgba="1 1 1 1" />
      </material>
    </visual>
  </link>
  <joint
    name="lidar1_joint"
    type="fixed">
    <origin
         xyz="-0.02 0 0.1"
        rpy="0 0 -1.57" />
    <parent
      link="base_link" />
    <child
      link="lidar1" />
  </joint> -->
<!-- Transmissions -->
  
	<transmission name="moolabot_front_left_joint_transmission">
	  <type>transmission_interface/SimpleTransmission</type>
	  <joint name="moolabot_front_left_joint">
		<hardwareInterface>hardware_interface/VelocityJointInterface</hardwareInterface>  
	  </joint>
	  <actuator name="moolabot_front_left_joint_actuator">
		<mechanicalReduction>7</mechanicalReduction>
		<hardwareInterface>VelocityJointInterface</hardwareInterface>
	  </actuator>
	</transmission>

	<transmission name="moolabot_front_right_joint_transmission">
	  <type>transmission_interface/SimpleTransmission</type>
	  <joint name="moolabot_front_right_joint">
		<hardwareInterface>hardware_interface/VelocityJointInterface</hardwareInterface>  
	  </joint>
	  <actuator name="moolabot_front_right_joint_actuator">
		<mechanicalReduction>7</mechanicalReduction>
		<hardwareInterface>VelocityJointInterface</hardwareInterface>
	  </actuator>
	</transmission>
	
	<transmission name="moolabot_rear_left_transmission">
	  <type>transmission_interface/SimpleTransmission</type>
	  <joint name="moolabot_rear_left_joint">
		<hardwareInterface>hardware_interface/VelocityJointInterface</hardwareInterface>  
	  </joint>
	  <actuator name="moolabot_rear_left_actuator">
		<mechanicalReduction>7</mechanicalReduction>
		<hardwareInterface>VelocityJointInterface</hardwareInterface>
	  </actuator>
	</transmission>

	<transmission name="moolabot_rear_right_transmission">
	  <type>transmission_interface/SimpleTransmission</type>
	  <joint name="moolabot_rear_right_joint">
		<hardwareInterface>hardware_interface/VelocityJointInterface</hardwareInterface>  
	  </joint>
	  <actuator name="moolabot_rear_right_actuator">
		<mechanicalReduction>7</mechanicalReduction>
		<hardwareInterface>VelocityJointInterface</hardwareInterface>
	  </actuator>
	</transmission>
	<transmission name="moolabot_rear_left_rocker_center_transmission">
	  <type>transmission_interface/SimpleTransmission</type>
	  <joint name="moolabot_rear_left_rocker_center_joint">
		<hardwareInterface>hardware_interface/VelocityJointInterface</hardwareInterface>  
	  </joint>
	  <actuator name="moolabot_rear_left_rocker_center_actuator">
		<mechanicalReduction>7</mechanicalReduction>
		<hardwareInterface>VelocityJointInterface</hardwareInterface>
	  </actuator>
	</transmission>

	<transmission name="moolabot_rear_right_rocker_center_transmission">
	  <type>transmission_interface/SimpleTransmission</type>
	  <joint name="moolabot_rear_right_rocker_center_joint">
		<hardwareInterface>hardware_interface/VelocityJointInterface</hardwareInterface>  
	  </joint>
	  <actuator name="moolabot_rear_right_rocker_center_actuator">
		<mechanicalReduction>7</mechanicalReduction>
		<hardwareInterface>VelocityJointInterface</hardwareInterface>
	  </actuator>
	</transmission>
	
	<transmission name="moolabot_rear_left_rocker_rear_transmission">
	  <type>transmission_interface/SimpleTransmission</type>
	  <joint name="moolabot_rear_left_rocker_rear_joint">
		<hardwareInterface>hardware_interface/VelocityJointInterface</hardwareInterface>  
	  </joint>
	  <actuator name="moolabot_rear_left_rocker_rear_actuator">
		<mechanicalReduction>7</mechanicalReduction>
		<hardwareInterface>VelocityJointInterface</hardwareInterface>
	  </actuator>
	</transmission>

	<transmission name="moolabot_rear_right_rocker_rear_transmission">
	  <type>transmission_interface/SimpleTransmission</type>
	  <joint name="moolabot_rear_right_rocker_rear_joint">
		<hardwareInterface>hardware_interface/VelocityJointInterface</hardwareInterface>  
	  </joint>
	  <actuator name="moolabot_rear_right_rocker_rear_actuator">
		<mechanicalReduction>7</mechanicalReduction>
		<hardwareInterface>VelocityJointInterface</hardwareInterface>
	  </actuator>
	</transmission>

<!--Differential Drive plugin-->
  <gazebo>
    <plugin name="front_wheel_controller" filename="libgazebo_ros_diff_drive.so">
      <commandTopic>cmd_vel</commandTopic>
      <odometryTopic>odom</odometryTopic>
      <odometryFrame>odom</odometryFrame>
      <odometrySource>world</odometrySource>
      <publishOdomTF>true</publishOdomTF>
      <robotBaseFrame>base_link</robotBaseFrame>
      <publishWheelTF>false</publishWheelTF>
      <publishTf>true</publishTf>
      <publishWheelJointState>true</publishWheelJointState>
      <legacyMode>false</legacyMode>
      <updateRate>30</updateRate>
      <leftJoint>moolabot_front_left_joint</leftJoint>
      <rightJoint>moolabot_front_right_joint</rightJoint>
      <wheelSeparation>0.48</wheelSeparation>
      <wheelDiameter>0.199687</wheelDiameter>
      <wheelAcceleration>1</wheelAcceleration>
      <wheelTorque>10</wheelTorque>
      <rosDebugLevel>na</rosDebugLevel>
    </plugin>
  </gazebo>
<!--Differential Drive plugin-->
  <gazebo>
    <plugin name="rear_wheel_controller" filename="libgazebo_ros_diff_drive.so">
      <commandTopic>cmd_vel</commandTopic>
      <odometryTopic>odom</odometryTopic>
      <odometryFrame>odom</odometryFrame>
      <odometrySource>world</odometrySource>
      <publishOdomTF>true</publishOdomTF>
      <robotBaseFrame>base_link</robotBaseFrame>
      <publishWheelTF>false</publishWheelTF>
      <publishTf>true</publishTf>
      <publishWheelJointState>true</publishWheelJointState>
      <legacyMode>false</legacyMode>
      <updateRate>30</updateRate>
      <leftJoint>moolabot_rear_left_rocker_rear_joint</leftJoint>
      <rightJoint>moolabot_rear_right_rocker_rear_joint</rightJoint>
      <wheelSeparation>0.48</wheelSeparation>
      <wheelDiameter>0.199687</wheelDiameter>
      <wheelAcceleration>1</wheelAcceleration>
      <wheelTorque>10</wheelTorque>
      <rosDebugLevel>na</rosDebugLevel>
    </plugin>
  </gazebo>
<!--Differential Drive plugin-->
  <gazebo>
    <plugin name="center_wheel_controller" filename="libgazebo_ros_diff_drive.so">
      <commandTopic>cmd_vel</commandTopic>
      <odometryTopic>odom</odometryTopic>
      <odometryFrame>odom</odometryFrame>
      <odometrySource>world</odometrySource>
      <publishOdomTF>true</publishOdomTF>
      <robotBaseFrame>base_link</robotBaseFrame>
      <publishWheelTF>false</publishWheelTF>
      <publishTf>true</publishTf>
      <publishWheelJointState>true</publishWheelJointState>
      <legacyMode>false</legacyMode>
      <updateRate>30</updateRate>
      <leftJoint>moolabot_rear_left_rocker_center_joint</leftJoint>
      <rightJoint>moolabot_rear_right_rocker_center_joint</rightJoint>
      <wheelSeparation>0.48</wheelSeparation>
      <wheelDiameter>0.199687</wheelDiameter>
      <wheelAcceleration>1</wheelAcceleration>
      <wheelTorque>10</wheelTorque>
      <rosDebugLevel>na</rosDebugLevel>
    </plugin>
  </gazebo>
<!--Lidar Gazebo plugin-->
<!--   <gazebo reference="lidar1">
    <material>Gazebo/FlatBlack</material>
    <sensor type="ray" name="lidar1">
      <pose>0 0 0 0 0 0</pose>
      <visualize>false</visualize>
      <update_rate>5</update_rate>
      <ray>
        <scan>
          <horizontal>
            <samples>360</samples>
            <resolution>1</resolution>
            <min_angle>0.0</min_angle>
            <max_angle>6.28319</max_angle>
          </horizontal>
        </scan>
        <range>
          <min>0.120</min>
          <max>4.5</max>
          <resolution>0.015</resolution>
        </range>
        <noise>
          <type>gaussian</type>
          <mean>0.0</mean>
          <stddev>0.01</stddev>
        </noise>
      </ray>
      <plugin name="lidar1_controller" filename="libgazebo_ros_laser.so">
        <topicName>scan</topicName>
        <frameName>lidar1</frameName>
      </plugin>
    </sensor>
  </gazebo> -->

</robot>
